Hi, currently `scipy.integrate.ode()` returns an error message indicating that
the function returned a tuple when it returns an array of non-matching length.
The true error message is buried above the raised `ValueError` here, which is
misleading, as the function is not returning a tuple.
Could a better error message be surfaced?
### Reproducing code example:
    import scipy.integrate
    def f(t, y):
        return [y[0]]
    scipy.integrate.ode(f).set_initial_value([1, 1]).integrate(1)
### Error message:
    unexpected array size: new_size=2, got array with arr_size=1
    rv_cb_arr is NULL
    Call-back cb_f_in_dvode__user__routines failed.
    Traceback (most recent call last):
      File "C:\Miniconda3\lib\site-packages\scipy\integrate\_ode.py", line 408, in integrate
        self.f_params, self.jac_params)
      File "C:\Miniconda3\lib\site-packages\scipy\integrate\_ode.py", line 865, in run
        y1, t, istate = self.runner(*args)
    SystemError:  returned NULL without setting an error
    During handling of the above exception, another exception occurred:
    Traceback (most recent call last):
      File "test.py", line 8, in 
        scipy.integrate.ode(f).set_initial_value([1, 1]).integrate(1)
      File "C:\Miniconda3\lib\site-packages\scipy\integrate\_ode.py", line 411, in integrate
        raise ValueError('Function to integrate must not return a tuple.')
    ValueError: Function to integrate must not return a tuple.
### Scipy/Numpy/Python version information:
    0.19.1 1.13.1 sys.version_info(major=3, minor=6, micro=1, releaselevel='final', serial=0)